Workbook

Sheet nse_sitemap_urls
A1: url | B1: parent | C1: child | D1: depth
A2: https://www.nseindia.com/ | D2: 0
A3: https://www.nseindia.com/invest/file-a-complaint-online | B3: invest | C3: file-a-complaint-online | D3: 2
A4: https://www.nseindia.com/invest/investors-awareness-programs | B4: invest | C4: investors-awareness-programs | D4: 2
A5: https://www.nseindia.com/products-services | C5: products-services | D5: 1
A6: https://www.nseindia.com/regulations/public-notice-compulsory-delisting | B6: regulations | C6: public-notice-compulsory-delisting | D6: 2
A7: https://www.nseindia.com/nse-copyright | C7: nse-copyright | D7: 1
A8: https://www.nseindia.com/market-data/securities-available-for-trading | B8: market-data | C8: securities-available-for-trading | D8: 2
A9: https://www.nseindia.com/invest/first-time-investor-products | B9: invest | C9: first-time-investor-products | D9: 2
A10: https://www.nseindia.com/regulations/listing-compliance | B10: regulations | C10: listing-compliance | D10: 2
A11: https://www.nseindia.com/market-data/stocks-in-call-auction | B11: market-data | C11: stocks-in-call-auction | D11: 2
A12: https://www.nseindia.com/website-policies | C12: website-policies | D12: 1
A13: https://www.nseindia.com/national-stock-exchange/about-nse-company | B13: national-stock-exchange | C13: about-nse-company | D13: 2
A14: https://www.nseindia.com/regulations/public-notice | B14: regulations | C14: public-notice | D14: 2
A15: https://www.nseindia.com/regulations/member-circulars-for-members | B15: regulations | C15: member-circulars-for-members | D15: 2
A16: https://www.nseindia.com/products-services/mf-about-mfss | B16: products-services | C16: mf-about-mfss | D16: 2
A17: https://www.nseindia.com/resources/exchange-communication-holidays | B17: resources | C17: exchange-communication-holidays | D17: 2
A18: https://www.nseindia.com/market-data/eod-historical-data-subscription | B18: market-data | C18: eod-historical-data-subscription | D18: 2
A19: https://www.nseindia.com/feedback/new | B19: feedback | C19: new | D19: 2
A20: https://www.nseindia.com/companies-listing/raising-capital-onboarding-process | B20: companies-listing | C20: raising-capital-onboarding-process | D20: 2
A21: https://www.nseindia.com/companies-listing/compliance-information-compliance-calendar-main-board | B21: companies-listing | C21: compliance-information-compliance-calendar-main-board | D21: 2
A22: https://www.nseindia.com/invest/find-a-stock-broker | B22: invest | C22: find-a-stock-broker | D22: 2
A23: https://www.nseindia.com/national-stock-exchange/nse-volume-business-growth | B23: national-stock-exchange | C23: nse-volume-business-growth | D23: 2
A24: https://www.nseindia.com/trade/members-compliance | B24: trade | C24: members-compliance | D24: 2
... A38: https://www.nseindia.com/trade/deposits-networth-requirements-for-membership | B38: trade | C38: deposits-networth-requirements-for-membership | D38: 2
A39: https://www.nseindia.com/nse-indices | C39: nse-indices | D39: 1
A40: https://www.nseindia.com/products-services/about-equity-derivatives | B40: products-services | C40: about-equity-derivatives | D40: 2
A41: https://www.nseindia.com/learn/academic-calendar | B41: learn | C41: academic-calendar | D41: 2
A42: https://www.nseindia.com/learn/process-to-register-ncfm-nse-certification-in-financial-markets | B42: learn | C42: process-to-register-ncfm-nse-certification-in-financial-markets | D42: 2
A43: https://www.nseindia.com/invest/about-arbitration | B43: invest | C43: about-arbitration | D43: 2
A44: https://www.nseindia.com/companies-listing/corporate-filings-financial-results | B44: companies-listing | C44: corporate-filings-financial-results | D44: 2
A45: https://www.nseindia.com/all-reports | C45: all-reports | D45: 1
A46: https://www.nseindia.com/companies-listing/corporate-filings-directory | B46: companies-listing | C46: corporate-filings-directory | D46: 2
A47: https://www.nseindia.com/trade/membership-suspension-expulsion | B47: trade | C47: membership-suspension-expulsion | D47: 2
A48: https://www.nseindia.com/companies-listing/corporate-filings-announcements | B48: companies-listing | C48: corporate-filings-announcements | D48: 2
A49: https://www.nseindia.com/trade/platform-services-connectivity | B49: trade | C49: platform-services-connectivity | D49: 2
A50: https://www.nseindia.com/market-data/data-subscription-fees | B50: market-data | C50: data-subscription-fees | D50: 2
A51: https://www.nseindia.com/learn/post-graduate-program-full-time | B51: learn | C51: post-graduate-program-full-time | D51: 2
A52: https://www.nseindia.com/all-reports-derivatives | C52: all-reports-derivatives | D52: 1
A53: https://www.nseindia.com/products-services/about-indices | B53: products-services | C53: about-indices | D53: 2
...

Sheet Sheet1
A1: url | B1: url | E1: 1 | F1: 2 | G1: 3 | H1: 4
A2: https://www.nseindia.com/ | B2: https: | D2: www.nseindia.com
A3: https://www.nseindia.com/invest/file-a-complaint-online | B3: https: | D3: www.nseindia.com | E3: invest | F3: file-a-complaint-online
A4: https://www.nseindia.com/invest/investors-awareness-programs | B4: https: | D4: www.nseindia.com | E4: invest | F4: investors-awareness-programs
A5: https://www.nseindia.com/products-services | B5: https: | D5: www.nseindia.com | E5: products-services
A6: https://www.nseindia.com/regulations/public-notice-compulsory-delisting | B6: https: | D6: www.nseindia.com | E6: regulations | F6: public-notice-compulsory-delisting
A7: https://www.nseindia.com/nse-copyright | B7: https: | D7: www.nseindia.com | E7: nse-copyright
A8: https://www.nseindia.com/market-data/securities-available-for-trading | B8: https: | D8: www.nseindia.com | E8: market-data | F8: securities-available-for-trading
A9: https://www.nseindia.com/invest/first-time-investor-products | B9: https: | D9: www.nseindia.com | E9: invest | F9: first-time-investor-products
A10: https://www.nseindia.com/regulations/listing-compliance | B10: https: | D10: www.nseindia.com | E10: regulations | F10: listing-compliance
A11: https://www.nseindia.com/market-data/stocks-in-call-auction | B11: https: | D11: www.nseindia.com | E11: market-data | F11: stocks-in-call-auction
A12: https://www.nseindia.com/website-policies | B12: https: | D12: www.nseindia.com | E12: website-policies
A13: https://www.nseindia.com/national-stock-exchange/about-nse-company | B13: https: | D13: www.nseindia.com | E13: national-stock-exchange | F13: about-nse-company
A14: https://www.nseindia.com/regulations/public-notice | B14: https: | D14: www.nseindia.com | E14: regulations | F14: public-notice
A15: https://www.nseindia.com/regulations/member-circulars-for-members | B15: https: | D15: www.nseindia.com | E15: regulations | F15: member-circulars-for-members
A16: https://www.nseindia.com/products-services/mf-about-mfss | B16: https: | D16: www.nseindia.com | E16: products-services | F16: mf-about-mfss
A17: https://www.nseindia.com/resources/exchange-communication-holidays | B17: https: | D17: www.nseindia.com | E17: resources | F17: exchange-communication-holidays
A18: https://www.nseindia.com/market-data/eod-historical-data-subscription | B18: https: | D18: www.nseindia.com | E18: market-data | F18: eod-historical-data-subscription
A19: https://www.nseindia.com/feedback/new | B19: https: | D19: www.nseindia.com | E19: feedback | F19: new
A20: https://www.nseindia.com/companies-listing/raising-capital-onboarding-process | B20: https: | D20: www.nseindia.com | E20: companies-listing | F20: raising-capital-onboarding-process
A21: https://www.nseindia.com/companies-listing/compliance-information-compliance-calendar-main-board | B21: https: | D21: www.nseindia.com | E21: companies-listing | F21: compliance-information-compliance-calendar-main-board
A22: https://www.nseindia.com/invest/find-a-stock-broker | B22: https: | D22: www.nseindia.com | E22: invest | F22: find-a-stock-broker
A23: https://www.nseindia.com/national-stock-exchange/nse-volume-business-growth | B23: https: | D23: www.nseindia.com | E23: national-stock-exchange | F23: nse-volume-business-growth
A24: https://www.nseindia.com/trade/members-compliance | B24: https: | D24: www.nseindia.com | E24: trade | F24: members-compliance
... A38: https://www.nseindia.com/trade/deposits-networth-requirements-for-membership | B38: https: | D38: www.nseindia.com | E38: trade | F38: deposits-networth-requirements-for-membership
A39: https://www.nseindia.com/nse-indices | B39: https: | D39: www.nseindia.com | E39: nse-indices
A40: https://www.nseindia.com/products-services/about-equity-derivatives | B40: https: | D40: www.nseindia.com | E40: products-services | F40: about-equity-derivatives
A41: https://www.nseindia.com/learn/academic-calendar | B41: https: | D41: www.nseindia.com | E41: learn | F41: academic-calendar
A42: https://www.nseindia.com/learn/process-to-register-ncfm-nse-certification-in-financial-markets | B42: https: | D42: www.nseindia.com | E42: learn | F42: process-to-register-ncfm-nse-certification-in-financial-markets
A43: https://www.nseindia.com/invest/about-arbitration | B43: https: | D43: www.nseindia.com | E43: invest | F43: about-arbitration
A44: https://www.nseindia.com/companies-listing/corporate-filings-financial-results | B44: https: | D44: www.nseindia.com | E44: companies-listing | F44: corporate-filings-financial-results
A45: https://www.nseindia.com/all-reports | B45: https: | D45: www.nseindia.com | E45: all-reports
A46: https://www.nseindia.com/companies-listing/corporate-filings-directory | B46: https: | D46: www.nseindia.com | E46: companies-listing | F46: corporate-filings-directory
A47: https://www.nseindia.com/trade/membership-suspension-expulsion | B47: https: | D47: www.nseindia.com | E47: trade | F47: membership-suspension-expulsion
A48: https://www.nseindia.com/companies-listing/corporate-filings-announcements | B48: https: | D48: www.nseindia.com | E48: companies-listing | F48: corporate-filings-announcements
A49: https://www.nseindia.com/trade/platform-services-connectivity | B49: https: | D49: www.nseindia.com | E49: trade | F49: platform-services-connectivity
A50: https://www.nseindia.com/market-data/data-subscription-fees | B50: https: | D50: www.nseindia.com | E50: market-data | F50: data-subscription-fees
A51: https://www.nseindia.com/learn/post-graduate-program-full-time | B51: https: | D51: www.nseindia.com | E51: learn | F51: post-graduate-program-full-time
A52: https://www.nseindia.com/all-reports-derivatives | B52: https: | D52: www.nseindia.com | E52: all-reports-derivatives
A53: https://www.nseindia.com/products-services/about-indices | B53: https: | D53: www.nseindia.com | E53: products-services | F53: about-indices
...

Sheet Sheet2
E1: part 1 | F1: count
E2: products-services | F2: =COUNTIF(Sheet1!$E$2:$E$1175,E2) -> 329
E3: get-quotes | F3: =COUNTIF(Sheet1!$E$2:$E$1175,E3) -> 230
E4: learn | F4: =COUNTIF(Sheet1!$E$2:$E$1175,E4) -> 111
E5: trade | F5: =COUNTIF(Sheet1!$E$2:$E$1175,E5) -> 75
E6: companies-listing | F6: =COUNTIF(Sheet1!$E$2:$E$1175,E6) -> 70
E7: market-data | F7: =COUNTIF(Sheet1!$E$2:$E$1175,E7) -> 52
E8: invest | F8: =COUNTIF(Sheet1!$E$2:$E$1175,E8) -> 50
E9: resources | F9: =COUNTIF(Sheet1!$E$2:$E$1175,E9) -> 32
E10: regulations | F10: =COUNTIF(Sheet1!$E$2:$E$1175,E10) -> 31
E11: nse-clearing | F11: =COUNTIF(Sheet1!$E$2:$E$1175,E11) -> 29
E12: nse-foundation | F12: =COUNTIF(Sheet1!$E$2:$E$1175,E12) -> 14
E13: nse-international-exchange | F13: =COUNTIF(Sheet1!$E$2:$E$1175,E13) -> 13
... E77: market-timings-holidays | F77: =COUNTIF(Sheet1!$E$2:$E$1175,E77) -> 1

Sheet Sheet4

Sheet products-services
E1: child1 | F1: child2 | G1: child3
C2: products-services | D2: about-commodity-derivatives
D3: about-corporate-bonds
D4: about-currency-derivatives
D5: about-electronic-bidding-platform | E5: documents-for-ncd-issues | F5: circulars | G5: operating-guidelines
D6: about-equity-derivatives
D7: about-equity-market
D8: about-etfs
D9: about-indices
D10: about-initial-public-offerings
D11: about-innovators-growth-platform
D12: about-institutional-placement-program
D13: about-interest-rate-derivatives
D14: about-negotiated-trade-reporting-platform
D15: about-nmf-getting-on-to
D16: about-nmf-platform
D17: about-nmf-platform-key-benefits
... D326: tri-party-repo-timings-holidays
